Workbook
Name __Validation_Relationships: Validation!$A:$A

Sheet RelationshipStats
A3: Count of sourceNodeValue | B3: Column Labels
A4: Row Labels | B4: Authority | C4: AuthorityGroup | D4: ControllingOrg | E4: (blank) | F4: Format | G4: Grand Total
A5: Authority | B5: 523 | C5: 279 | F5: 1 | G5: 803
A6: DEFINES | F6: 1 | G6: 1
A7: DEPRECATES | B7: 7 | G7: 7
A8: EXTENDS | C8: 1 | G8: 1
A9: HAS_RELATED_AUTHORITY | B9: 138 | C9: 13 | G9: 151
A10: MEMBER_OF | C10: 254 | G10: 254
A11: OBSOLETES | B11: 58 | G11: 58
A12: REFERENCES | B12: 16 | C12: 4 | G12: 20
A13: SUPERSEDES | B13: 98 | C13: 7 | G13: 105
A14: UPDATES | B14: 206 | G14: 206
A15: AuthorityGroup | B15: 13 | C15: 13 | F15: 18 | G15: 44
A16: DEFINES | F16: 18 | G16: 18
A17: HAS_RELATED_AUTHORITY | B17: 13 | C17: 2 | G17: 15
A18: MEMBER_OF | C18: 11 | G18: 11
A19: ControllingOrg | B19: 291 | D19: 128 | G19: 419
A20: CONTROLS | B20: 291 | G20: 291
A21: HAS_AFFILIATE_ORG | D21: 13 | G21: 13
A22: HAS_CHILD_ORG | D22: 90 | G22: 90
A23: PREVIOUSLY_KNOWN_AS | D23: 22 | G23: 22
A24: SUCCEEDED_ORG | D24: 3 | G24: 3
A25: (blank)
A26: ALSO_PUBLISHED_AS
A27: CONTAINS
A28: CONTROLS
A29: DEFINES
A30: DRAFTED_BY
A31: EXTENDS
A32: HAS_REVISION
A33: IMPLEMENTS
A34: OBSOLETES
A35: PROFILES
A36: REFERENCES
... A38: (blank)
A39: Grand Total | B39: 827 | C39: 292 | D39: 128 | F39: 19 | G39: 1266

Sheet Relationships
A1: relationshipId | B1: createdTimestamp | C1: updatedTimestamp | D1: relationshipType | E1: sourceNodeType | F1: sourceNodeAttr | G1: sourceNodeValue | H1: sourceNodeValue_old | I1: targetNodeType | J1: targetNodeAttr | K1: targetNodeValue | L1: target:END_ID | M1: affiliation | N1: referenceType | O1: authoritySection | P1: relationship | Q1: notes | R1: DNI_notes
D2: HAS_CHILD_ORG | E2: ControllingOrg | F2: shortName | G2: ISO | H2: ISO | I2: ControllingOrg | J2: shortName | K2: ISO/IEC JTC 1 | L2: ISO/IEC JTC 1
D3: HAS_CHILD_ORG | E3: ControllingOrg | F3: shortName | G3: IEC | H3: IEC | I3: ControllingOrg | J3: shortName | K3: ISO/IEC JTC 1 | L3: ISO/IEC JTC 1
D4: SUCCEEDED_ORG | E4: ControllingOrg | F4: shortName | G4: ISO/IEC JTC 1 | I4: ControllingOrg | J4: shortName | K4: ISO TC 97
D5: SUCCEEDED_ORG | E5: ControllingOrg | F5: shortName | G5: ISO/IEC JTC 1 | I5: ControllingOrg | J5: shortName | K5: IEC TC 83
D6: HAS_CHILD_ORG | E6: ControllingOrg | F6: shortName | G6: ISO/IEC JTC 1 | I6: ControllingOrg | J6: shortName | K6: JTC1 SC 2
D7: PREVIOUSLY_KNOWN_AS | E7: ControllingOrg | F7: shortName | G7: JTC1 SC 2 | I7: ControllingOrg | J7: shortName | K7: TC97 SC 2
D8: HAS_CHILD_ORG | E8: ControllingOrg | F8: shortName | G8: ISO/IEC JTC 1 | I8: ControllingOrg | J8: shortName | K8: JTC1 SC 17
D9: HAS_CHILD_ORG | E9: ControllingOrg | F9: shortName | G9: ISO/IEC JTC 1 | I9: ControllingOrg | J9: shortName | K9: JTC1 SC 27
D10: HAS_CHILD_ORG | E10: ControllingOrg | F10: shortName | G10: ISO/IEC JTC 1 | I10: ControllingOrg | J10: shortName | K10: JTC1 SC 37
D11: HAS_CHILD_ORG | E11: ControllingOrg | F11: shortName | G11: ISO | I11: ControllingOrg | J11: shortName | K11: ISO TC 46
D12: HAS_CHILD_ORG | E12: ControllingOrg | F12: shortName | G12: ISO | I12: ControllingOrg | J12: shortName | K12: ISO TC 97
D13: HAS_CHILD_ORG | E13: ControllingOrg | F13: shortName | G13: ISO | I13: ControllingOrg | J13: shortName | K13: ISO TC 154
D14: HAS_CHILD_ORG | E14: ControllingOrg | F14: shortName | G14: ISO TC 97 | I14: ControllingOrg | J14: shortName | K14: TC97 SC 2
D16: HAS_CHILD_ORG | E16: ControllingOrg | F16: shortName | G16: ITU | I16: ControllingOrg | J16: shortName | K16: CCITT (ITU-T)
... D202: PREVIOUSLY_KNOWN_AS | E202: ControllingOrg | F202: shortName | G202: OEMI (ITI) | I202: ControllingOrg | J202: shortName | K202: NAOAM (ITI)
D203: HAS_AFFILIATE_ORG | E203: ControllingOrg | F203: shortName | G203: ANSI | I203: ControllingOrg | J203: shortName | K203: INCITS | M203: accredits
D204: HAS_AFFILIATE_ORG | E204: ControllingOrg | F204: shortName | G204: ANSI | I204: ControllingOrg | J204: shortName | K204: NCITS (INCITS) | M204: accredits
D205: HAS_AFFILIATE_ORG | E205: ControllingOrg | F205: shortName | G205: ANSI | I205: ControllingOrg | J205: shortName | K205: X3 (INCITS) | M205: accredits
D206: HAS_AFFILIATE_ORG | E206: ControllingOrg | F206: shortName | G206: USASI (ANSI) | I206: ControllingOrg | J206: shortName | K206: X3 (INCITS) | M206: accredits
D207: HAS_AFFILIATE_ORG | E207: ControllingOrg | F207: shortName | G207: ASA (ANSI) | I207: ControllingOrg | J207: shortName | K207: X3 (INCITS) | M207: accredits
D208: HAS_AFFILIATE_ORG | E208: ControllingOrg | F208: shortName | G208: ITI | I208: ControllingOrg | J208: shortName | K208: INCITS | M208: sponsors
D209: HAS_AFFILIATE_ORG | E209: ControllingOrg | F209: shortName | G209: ITI | I209: ControllingOrg | J209: shortName | K209: NCITS (INCITS) | M209: sponsors
D210: HAS_AFFILIATE_ORG | E210: ControllingOrg | F210: shortName | G210: ITI | I210: ControllingOrg | J210: shortName | K210: X3 (INCITS) | M210: sponsors
D211: HAS_AFFILIATE_ORG | E211: ControllingOrg | F211: shortName | G211: CBEMA (ITI) | I211: ControllingOrg | J211: shortName | K211: X3 (INCITS) | M211: sponsors
D212: HAS_AFFILIATE_ORG | E212: ControllingOrg | F212: shortName | G212: BEMA (ITI) | I212: ControllingOrg | J212: shortName | K212: X3 (INCITS) | M212: sponsors
D213: HAS_AFFILIATE_ORG | E213: ControllingOrg | F213: shortName | G213: ANSI | I213: ControllingOrg | J213: shortName | K213: ISO | M213: national representative
D214: HAS_CHILD_ORG | E214: ControllingOrg | F214: shortName | G214: ANSI | I214: ControllingOrg | J214: shortName | K214: USNC (ANSI)
D215: HAS_AFFILIATE_ORG | E215: ControllingOrg | F215: shortName | G215: USNC (ANSI) | I215: ControllingOrg | J215: shortName | K215: IEC | M215: national representative
D216: HAS_AFFILIATE_ORG | E216: ControllingOrg | F216: shortName | G216: INCITS/L2 | I216: ControllingOrg | J216: shortName | K216: JTC1 SC 2 | M216: technical advisory group
D218: PREVIOUSLY_KNOWN_AS | E218: ControllingOrg | F218: shortName | G218: Ecma | I218: ControllingOrg | J218: shortName | K218: ECMA (Ecma)
D219: HAS_CHILD_ORG | E219: ControllingOrg | F219: shortName | G219: Ecma | I219: ControllingOrg | J219: shortName | K219: ECMA TC1
D220: HAS_CHILD_ORG | E220: ControllingOrg | F220: shortName | G220: ECMA (Ecma) | I220: ControllingOrg | J220: shortName | K220: ECMA TC1
D222: HAS_CHILD_ORG | E222: ControllingOrg | F222: shortName | G222: IETF | I222: ControllingOrg | J222: shortName | K222: IETF GEN Area
D223: HAS_CHILD_ORG | E223: ControllingOrg | F223: shortName | G223: IETF | I223: ControllingOrg | J223: shortName | K223: IETF SEC Area
D224: HAS_CHILD_ORG | E224: ControllingOrg | F224: shortName | G224: IETF SEC Area | H224: IETF | I224: ControllingOrg | J224: shortName | K224: oauth WG | L224: oauth WG
D225: HAS_CHILD_ORG | E225: ControllingOrg | F225: shortName | G225: IETF SEC Area | H225: IETF | I225: ControllingOrg | J225: shortName | K225: jose WG | L225: jose WG
D226: HAS_CHILD_ORG | E226: ControllingOrg | F226: shortName | G226: IETF SEC Area | I226: ControllingOrg | J226: shortName | K226: scim WG
D227: HAS_CHILD_ORG | E227: ControllingOrg | F227: shortName | G227: IETF SEC Area | I227: ControllingOrg | J227: shortName | K227: cose WG
D228: HAS_CHILD_ORG | E228: ControllingOrg | F228: shortName | G228: IETF SEC Area | I228: ControllingOrg | J228: shortName | K228: spice WG
...

Sheet ControllingOrg
A1: controllingOrgId | B1: createdTimestamp | C1: updatedTimestamp | D1: shortName | E1: fullName | F1: url | G1: organizationType | H1: status | I1: startDate | J1: endDate | K1: notes | L1: DNI_notes
D2: IETF | E2: Internet Engineering Task Force | F2: https://www.ietf.org/ | G2: open standards organization | H2: Active | I2: 1986-01 | K2: IETF succeeds multiple organizations for managing the RFC series, starting in 1969
D3: IETF GEN Area | E3: IETF General Area Group | F3: https://datatracker.ietf.org/group/gen/about/ | G3: topic focus group | H3: Active | I3: 2002-11-17
D4: IETF SEC Area | E4: IETF Security Area Group | F4: https://datatracker.ietf.org/group/sec/about/ | G4: topic focus group | H4: Active | I4: 1983-09-06
D5: oauth WG | E5: Web Authorization Protocol working group | F5: https://datatracker.ietf.org/wg/oauth/about/ | G5: topic focus group | H5: Active | I5: 2009-05-12
D6: jose WG | E6: Javascript Object Signing and Encryption working group | F6: https://datatracker.ietf.org/wg/jose/about/ | G6: topic focus group | H6: Active | I6: 2011-09-21
D7: scim WG | E7: System for Cross-domain Identity Management working group | F7: https://datatracker.ietf.org/wg/scim/about/ | G7: topic focus group | H7: Active | I7: 2012-06-12
D8: cose WG | E8: CBOR Object Signing and Encryption working group | F8: https://datatracker.ietf.org/wg/cose/about/ | G8: topic focus group | H8: Active | I8: 2015-06-03
D9: spice WG | E9: Secure Patterns for Internet CrEdentials working group | F9: https://datatracker.ietf.org/wg/spice/about/ | G9: topic focus group | H9: Active | I9: 2023-09-28
D10: rats WG | E10: Remote ATtestation ProcedureS working group | F10: https://datatracker.ietf.org/wg/rats/about/ | G10: topic focus group | H10: Active | I10: 2018-09-26
D11: scitt WG | E11: Supply Chain Integrity, Transparency, and Trust working group | F11: https://datatracker.ietf.org/wg/scitt/about/ | G11: topic focus group | H11: Active | I11: 2022-06-02
D12: ace WG | E12: Authentication and Authorization for Constrained Environments working group | F12: https://datatracker.ietf.org/wg/ace/about/ | G12: topic focus group | H12: Active | I12: 2014-01-22
D13: httpauth WG | E13: Hypertext Transfer Protocol Authentication working group | F13: https://datatracker.ietf.org/wg/httpauth/about/ | G13: topic focus group | H13: Closed | I13: 2012 | J13: 2017-02-01 | K13: Start date unclear
D14: kitten WG | E14: Common Authentication Technology Next Generation working group | F14: https://datatracker.ietf.org/wg/kitten/about/ | G14: topic focus group | H14: Active | I14: 2004-10-28
D15: radext WG | E15: RADIUS EXTensions working group | F15: https://datatracker.ietf.org/wg/radext/about/ | G15: topic focus group | H15: Active | I15: 2004-07-08
D16: tls WG | E16: Transport Layer Security working group | F16: https://datatracker.ietf.org/wg/tls/about/ | G16: topic focus group | H16: Active | I16: 1996-05-24
D17: uta WG | E17: Using TLS in Applications | F17: https://datatracker.ietf.org/wg/uta/about/ | G17: topic focus group | H17: Active | I17: 2013-12-11
D18: IETF APP Area | E18: IETF Applications Area Group | F18: https://datatracker.ietf.org/group/app/about/ | G18: topic focus group | H18: Closed | I18: 1983-09-06
D19: drums WG | E19: Detailed Revision/Update of Message Standards working group | F19: https://datatracker.ietf.org/wg/drums/about/ | G19: topic focus group | H19: Closed | I19: 1995-05-18 | J19: 2001-04-26
D20: http WG | E20: HyperText Transfer Protocol working group | F20: https://datatracker.ietf.org/wg/http/about/ | G20: topic focus group | H20: Closed | I20: 1995-01-26 | J20: 2000-10-11
D21: tn3270e WG | E21: Telnet TN3270 Enhancements working group | F21: https://datatracker.ietf.org/wg/tn3270e/about/ | G21: topic focus group | H21: Closed | I21: 1997-03-24 | J21: 2004-02-19
D22: uribof WG | E22: Uniform Resource Identifiers working group | F22: https://datatracker.ietf.org/wg/uribof/about/ | G22: topic focus group | H22: Closed | I22: 1992-11-30 | J22: 1995-07-21
D23: urlreg WG | E23: Uniform Resource Locator Registration Procedures working group | F23: https://datatracker.ietf.org/wg/urlreg/about/ | G23: topic focus group | H23: Closed | I23: 1997-07-24 | J23: 1999-11-15
D24: IETF ART Area | E24: IETF Applications and Real-Time Area Group | F24: https://datatracker.ietf.org/group/art/about/ | G24: topic focus group | H24: Active | I24: 2015-05-28
D25: appsawg WG | E25: ART Area General Applications working group | F25: https://datatracker.ietf.org/wg/appsawg/about/ | G25: topic focus group | H25: Closed | I25: 2010-10-26 | J25: 2017-07-06
D26: wimse WG | E26: Workload Identity in Multi System Environments working group | F26: https://datatracker.ietf.org/wg/wimse/about/ | G26: topic focus group | H26: Active | I26: 2023-09-28
D27: xmpp WG | E27: Extensible Messaging and Presence Protocol working group | F27: https://datatracker.ietf.org/wg/xmpp/about/ | G27: topic focus group | H27: Closed | I27: 2009-05-29 | J27: 2015-09-14
D28: IETF INT Area | E28: IETF Internet Area Group | F28: https://datatracker.ietf.org/group/int/about/ | G28: topic focus group | H28: Active | I28: 1983-09-06
D29: 6man WG | E29: IPv6 Maintenance working group | F29: https://datatracker.ietf.org/wg/6man/about/ | G29: topic focus group | H29: Active | I29: 2007-09-20
D30: ipngwg WG | E30: IPNG working group | F30: https://datatracker.ietf.org/wg/ipngwg/about/ | G30: topic focus group | H30: Closed | I30: 1994-11-17 | J30: 2001-12-06
D31: ipv6 WG | E31: IP Version 6 working group | F31: https://datatracker.ietf.org/wg/ipv6/about/ | G31: topic focus group | H31: Closed | I31: 2000-12-05 | J31: 2007-09-23
D32: IETF WIT Area | E32: Web and Internet Transport Area Group | F32: https://datatracker.ietf.org/group/wit/about/ | G32: topic focus group | H32: Active | K32: Start date unclear
D33: httpbis WG | E33: HTTP working group | F33: https://datatracker.ietf.org/wg/httpbis/about/ | G33: topic focus group | H33: Active | I33: 2007-10-18
D34: quic WG | E34: QUIC working group | F34: https://datatracker.ietf.org/wg/quic/about/ | G34: topic focus group | H34: Active | I34: 2016-10-04
D35: OIDF | E35: OpenID Foundation | F35: https://openid.net/ | G35: open standards organization | H35: Active | I35: 2007
D36: AB/Connect WG | E36: OpenID AB/Connect working group | F36: https://openid.net/wg/connect/ | G36: topic focus group | H36: Active | I36: 2010-03
D37: AuthZEN WG | E37: AuthZEN working group | F37: https://openid.net/wg/authzen/ | G37: topic focus group | H37: Active | I37: 2023-10
D38: DCP WG | E38: Digital Credentials Protocols working group | F38: https://openid.net/wg/digital-credentials-protocols/ | G38: topic focus group | H38: Active | I38: 2023-08
D39: EAP WG | E39: Enhanced Authentication Profile working group | F39: https://openid.net/wg/eap/ | G39: topic focus group | H39: Closed | I39: 2016-07 | J39: 2025-06
D40: eKYC-IDA WG | E40: eKYC and Identity Assurance working group | F40: https://openid.net/wg/ekyc-ida/ | G40: topic focus group | H40: Active | I40: 2019-12
...

Sheet AuthorityGroup
A1: authorityGroupId | B1: createdTimestamp | C1: updatedTimestamp | D1: atlasStatus | E1: groupType | F1: reference | G1: title | H1: url | I1: notes | J1: DNI_notes
D2: refonly | E2: versionedAuthority | F2: US-ASCII | G2: American Standard Code for Information Interchange
D3: refonly | E3: versionedAuthority | F3: ECMA-6 | G3: 7-Bit Coded Character Set | H3: https://ecma-international.org/publications-and-standards/standards/ecma-6/
D4: refonly | E4: versionedAuthority | F4: ISO/IEC 646 | G4: Information Processing - ISO 7-bit Coded Character Set for Information Interchange
D5: refonly | E5: versionedAuthority | F5: ITU-T Rec. T.50 | G5: International Reference Alphabet (IRA) / Information Processing - ISO 7-bit Coded Character Set for Information Interchange | H5: https://www.itu.int/myworkspace/#/t-rec/item?id=2570
D6: refonly | E6: versionedAuthority | F6: ECMA-35 | G6: Character Code Structure and Extension Techniques | H6: https://ecma-international.org/publications-and-standards/standards/ecma-35/
D7: refonly | E7: versionedAuthority | F7: ISO/IEC 2022 | G7: Information technology — Character code structure and extension techniques
D8: refonly | E8: collectedAuthority | F8: ISO/IEC 2022:1994 (as amended) | G8: Information technology — Character code structure and extension techniques [ISO/IEC 2022:1994] | H8: https://www.iso.org/standard/22747.html
D9: refonly | E9: versionedAuthority | F9: ISO/IEC 2375 | G9: Information technology – Registered escape sequences and coded character sets
D10: refonly | E10: versionedAuthority | F10: ECMA-43 | G10: 8-Bit Coded Character Set Structure and Rules | H10: https://ecma-international.org/publications-and-standards/standards/ecma-43/
D11: refonly | E11: versionedAuthority | F11: ISO/IEC 4873 | G11: Information technology — ISO 8-bit code for information interchange — Structure and rules for implementation
D12: refonly | E12: collectedAuthority | F12: ISO 4873:1979 (as amended) | G12: Information processing — 8- bit coded character set for information interchange [ISO 4873:1979]
D13: refonly | E13: versionedAuthority | F13: ECMA-48 | G13: Control Functions for Coded Character Sets | H13: https://ecma-international.org/publications-and-standards/standards/ecma-48/
D14: refonly | E14: versionedAuthority | F14: ISO/IEC 6429 | G14: Information technology — Control functions for coded character sets
D15: refonly | E15: versionedAuthority | F15: ISO/IEC 6937 | G15: Information technology — Coded graphic character set for text communication — Latin alphabet
D16: refonly | E16: collectedAuthority | F16: ISO 6937-2:1983 (as amended) | G16: Information processing — Coded character sets for text communication — Part 2: Latin alphabetic and non-alphabetic graphic characters
D17: refonly | E17: versionedAuthority | F17: ITU-T Rec. T.51 | G17: Latin Based Coded Character Sets for Telematic Services
D18: refonly | E18: collectedAuthority | F18: ITU-T Rec. T.51 (09/1992) (as amended) | G18: Latin Based Coded Character Sets for Telematic Services
D19: refonly | E19: collectedAuthority | F19: ISO/IEC 8859 | G19: Information technology — 8-bit single-byte coded graphic character sets
D20: refonly | E20: versionedAuthority | F20: ISO/IEC 10367 | G20: Information technology — Standardized coded graphic character sets for use in 8-bit codes
D21: refonly | E21: versionedAuthority | F21: ITU-T Rec. T.61 | G21: Character Repertoire and Coded Character Sets for the International Teletex Service
D22: refonly | E22: versionedAuthority | F22: Unicode | G22: The Unicode Standard | H22: https://www.unicode.org/versions/enumeratedversions.html
D23: refonly | E23: versionedAuthority | F23: ISO/IEC 10646 | G23: Information technology — Universal Multiple-Octet Coded Character Set (UCS)
D24: refonly | E24: collectedAuthority | F24: ISO/IEC 10646-1:1993 (as amended) | G24: Information technology — Universal Multiple-Octet Coded Character Set (UCS) — Part 1: Architecture and Basic Multilingual Plane [ISO/IEC 10646-1:1993] | H24: https://www.iso.org/standard/18741.html
D25: refonly | E25: collectedAuthority | F25: ISO/IEC 10646-1:1993 (Unicode 2.0) | G25: Information technology — Universal Multiple-Octet Coded Character Set (UCS) — Part 1: Architecture and Basic Multilingual Plane [ISO/IEC 10646-1:1993] (equivalent to Unicode 2.0) | I25: Subset of amendments to ISO/IEC 10464-1:1993 for Unicode equivalence
D26: refonly | E26: collectedAuthority | F26: ISO/IEC 10646-1:2000 (as amended) | G26: Information technology — Universal Multiple-Octet Coded Character Set (UCS) — Part 1: Architecture and Basic Multilingual Plane [ISO/IEC 10646-1:2000] | H26: https://www.iso.org/standard/29819.html
D27: refonly | E27: collectedAuthority | F27: ISO/IEC 10646:2000/2001 (Unicode 3.1) | G27: Information technology — Universal Multiple-Octet Coded Character Set (UCS) [ISO/IEC 10646-1:2000 and ISO/IEC 10646-2:2001] (equivalent to Unicode 3.1) | I27: Combination of ISO/IEC 10646-1:2000 and ISO/IEC 10646-2:2001 for Unicode equivalence
D28: refonly | E28: collectedAuthority | F28: ISO/IEC 10646:2000/2001 (Unicode 3.2) | G28: Information technology — Universal Multiple-Octet Coded Character Set (UCS) [ISO/IEC 10646-1:2000 and ISO/IEC 10646-2:2001] (equivalent to Unicode 3.2) | I28: Combination of ISO/IEC 10646-1:2000 (amended) and ISO/IEC 10646-2:2001 for Unicode equivalence
D29: refonly | E29: collectedAuthority | F29: ISO/IEC 10646:2003 (as amended) | G29: Information technology — Universal Multiple-Octet Coded Character Set (UCS) [ISO/IEC 10646:2003] | H29: https://www.iso.org/standard/39921.html
D30: refonly | E30: collectedAuthority | F30: ISO/IEC 10646:2003 (Unicode 4.1) | G30: Information technology — Universal Multiple-Octet Coded Character Set (UCS) [ISO/IEC 10646:2003] (equivalent to Unicode 4.1) | I30: Subset of amendments to ISO/IEC 10464:2003 for Unicode equivalence
D31: refonly | E31: collectedAuthority | F31: ISO/IEC 10646:2003 (Unicode 5.0) | G31: Information technology — Universal Multiple-Octet Coded Character Set (UCS) [ISO/IEC 10646:2003] (equivalent to Unicode 5.0) | I31: Subset of amendments to ISO/IEC 10464:2003 for Unicode equivalence
D32: refonly | E32: collectedAuthority | F32: ISO/IEC 10646:2003 (Unicode 5.1) | G32: Information technology — Universal Multiple-Octet Coded Character Set (UCS) [ISO/IEC 10646:2003] (equivalent to Unicode 5.1) | I32: Subset of amendments to ISO/IEC 10464:2003 for Unicode equivalence
D33: refonly | E33: collectedAuthority | F33: ISO/IEC 10646:2003 (Unicode 5.2) | G33: Information technology — Universal Multiple-Octet Coded Character Set (UCS) [ISO/IEC 10646:2003] (equivalent to Unicode 5.2) | I33: Subset of amendments to ISO/IEC 10464:2003 for Unicode equivalence
D34: refonly | E34: collectedAuthority | F34: ISO/IEC 10646:2012 (as amended) | G34: Information technology — Universal Multiple-Octet Coded Character Set (UCS) [ISO/IEC 10646:2012] | H34: https://www.iso.org/standard/56921.html
D35: refonly | E35: collectedAuthority | F35: ISO/IEC 10646:2014 (as amended) | G35: Information technology — Universal Multiple-Octet Coded Character Set (UCS) [ISO/IEC 10646:2014] | H35: https://www.iso.org/standard/63182.html
D36: refonly | E36: collectedAuthority | F36: ISO/IEC 10646:2014 (Unicode 8.0) | G36: Information technology — Universal Multiple-Octet Coded Character Set (UCS) [ISO/IEC 10646:2014] (equivalent to Unicode 8.0) | I36: Subset of amendments to ISO/IEC 10464:2014 for Unicode equivalence
D37: refonly | E37: collectedAuthority | F37: ISO/IEC 10646:2014 (Unicode 9.0) | G37: Information technology — Universal Multiple-Octet Coded Character Set (UCS) [ISO/IEC 10646:2014] (equivalent to Unicode 9.0) | I37: Subset of amendments to ISO/IEC 10464:2014 for Unicode equivalence
D38: refonly | E38: collectedAuthority | F38: ISO/IEC 10646:2017 (as amended) | G38: Information technology — Universal Multiple-Octet Coded Character Set (UCS) [ISO/IEC 10646:2017] | H38: https://www.iso.org/standard/69119.html
D39: refonly | E39: collectedAuthority | F39: ISO/IEC 10646:2017 (Unicode 11.0) | G39: Information technology — Universal Multiple-Octet Coded Character Set (UCS) [ISO/IEC 10646:2017] (equivalent to Unicode 11.0) | I39: Subset of amendments to ISO/IEC 10464:2017 for Unicode equivalence
D40: refonly | E40: collectedAuthority | F40: ISO/IEC 10646:2017 (Unicode 12.0) | G40: Information technology — Universal Multiple-Octet Coded Character Set (UCS) [ISO/IEC 10646:2017] (equivalent to Unicode 12.0) | I40: Subset of amendments to ISO/IEC 10464:2017 for Unicode equivalence
...

Sheet Authority
A1: authorityId | B1: createdTimestamp | C1: updatedTimestamp | D1: atlasCategory | E1: atlasStatus | F1: reference | G1: versionTag | H1: title | I1: status | J1: type | K1: stream | L1: publishedDate | M1: canonicalUrl | N1: canonicalFormat | O1: plainTextUrl | P1: htmlUrl | Q1: otherUrl | R1: otherFormat | S1: notes | T1: DNI_notes
D2: characterSet | E2: refonly; relComplete | F2: US-ASCII [ASA X3.4-1963] | H2: American Standard Code for Information Interchange [ASA X3.4-1963] | I2: Superseded | J2: National Standard | L2: 1963-06-17
D3: characterSet | E3: noReview; refonly; relComplete | F3: US-ASCII [ASA X3.4-1965] | H3: American Standard Code for Information Interchange [ASA X3.4-1965] | I3: Unpublished; Superseded | J3: National Standard | L3: 1965
D4: characterSet | E4: refonly; relComplete | F4: US-ASCII [USAS X3.4-1967] | H4: USA Standard Code for Information Interchange [USAS X3.4-1967] | I4: Superseded | J4: National Standard | L4: 1967-07-07
D5: characterSet | E5: refonly; relComplete | F5: US-ASCII [USAS X3.4-1968] | H5: USA Standard Code for Information Interchange [USAS X3.4-1968] | I5: Superseded | J5: National Standard | L5: 1968-10-10
D6: characterSet | E6: refonly; relComplete | F6: US-ASCII [ANSI X3.4-1977] | H6: American National Standard Code for Information Interchange [ANSI X3.4-1977] | I6: Superseded | J6: National Standard | L6: 1977-06-09
D7: characterSet | E7: refonly; relComplete | F7: US-ASCII [ANSI X3.4-1986] | H7: American National Standard for Information Systems - Coded Character Sets - 7-Bit American National Standard Code for Information Interchange (7-Bit ASCII) [ANSI X3.4-1986] | I7: Superseded | J7: National Standard | L7: 1986-03-26
D8: characterSet | E8: noReview; refonly; relComplete | F8: US-ASCII [ANSI X3.4-1986 (R1992)] | H8: American National Standard for Information Systems - Coded Character Sets - 7-Bit American National Standard Code for Information Interchange (7-Bit ASCII) [ANSI X3.4-1986 (R1992)] | I8: Superseded | J8: National Standard | L8: 1992 | S8: Reaffirmation of ANSI X3.4-1986
D9: characterSet | E9: noReview; refonly; relComplete | F9: US-ASCII [ANSI X3.4-1986 (R1997)] | H9: American National Standard for Information Systems - Coded Character Sets - 7-Bit American National Standard Code for Information Interchange (7-Bit ASCII) [ANSI X3.4-1986 (R1997)] | I9: Superseded | J9: National Standard | L9: 1997 | S9: Reaffirmation of ANSI X3.4-1986
D10: characterSet | E10: noReview; refonly; relComplete | F10: US-ASCII [ANSI INCITS 4-1986 (R2002)] | H10: American National Standard for Information Systems - Coded Character Sets - 7-Bit American National Standard Code for Information Interchange (7-Bit ASCII) [ANSI INCITS 4-1986 (R2002)] | I10: Superseded | J10: National Standard | L10: 2002-12-30 | M10: https://webstore.ansi.org/standards/incits/ansiincits1986r2002 | N10: Purchase | S10: Reaffirmation of ANSI X3.4-1986
D11: characterSet | E11: refonly; relComplete | F11: US-ASCII [ANSI INCITS 4-1986 (R2007)] | H11: American National Standard for Information Systems - Coded Character Sets - 7-Bit American National Standard Code for Information Interchange (7-Bit ASCII) [ANSI INCITS 4-1986 (R2007)] | I11: Superseded | J11: National Standard | L11: 2007-06-14 | M11: https://webstore.ansi.org/standards/incits/ansiincits1986r2007 | N11: Purchase | S11: Reaffirmation of ANSI X3.4-1986
D12: characterSet | E12: noReview; refonly; relComplete | F12: US-ASCII [INCITS 4-1986 (R2012)] | H12: American National Standard for Information Systems - Coded Character Sets - 7-Bit American National Standard Code for Information Interchange (7-Bit ASCII) [INCITS 4-1986 (R2012)] | I12: Superseded | J12: National Standard | L12: 2012-06-15 | M12: https://webstore.ansi.org/standards/incits/incits1986r2012 | N12: Purchase | S12: Reaffirmation of ANSI X3.4-1986
D13: characterSet | E13: noReview; refonly; relComplete | F13: US-ASCII [INCITS 4-1986 (R2017)] | H13: American National Standard for Information Systems - Coded Character Sets - 7-Bit American National Standard Code for Information Interchange (7-Bit ASCII) [INCITS 4-1986 (R2017)] | I13: Superseded | J13: National Standard | L13: 2017-11-02 | M13: https://webstore.ansi.org/standards/incits/incits1986r2017 | N13: Purchase | S13: Reaffirmation of ANSI X3.4-1986
D14: characterSet | E14: noReview; refonly; relComplete | F14: US-ASCII [INCITS 4-1986 (R2022)] | H14: American National Standard for Information Systems - Coded Character Sets - 7-Bit American National Standard Code for Information Interchange (7-Bit ASCII) [INCITS 4-1986 (R2022)] | I14: Active | J14: National Standard | L14: 2022-09-08 | M14: https://webstore.ansi.org/standards/incits/incits1986r2022 | N14: Purchase | S14: Reaffirmation of ANSI X3.4-1986
D15: characterSet | E15: noReview; refonly; relComplete | F15: ECMA-6 (04/1965) | G15: Edition 1 | H15: 7-bit Coded Character Set [ECMA-6 (04/1965)] | I15: Superseded | J15: ECMA Standard | L15: 1965-04
D16: characterSet | E16: noReview; refonly; relComplete | F16: ECMA-6 (06/1967) | G16: Edition 2 | H16: 7-bit Coded Character Set [ECMA-6 (06/1967)] | I16: Superseded | J16: ECMA Standard | L16: 1967-06
D17: characterSet | E17: noReview; refonly; relComplete | F17: ECMA-6 (07/1970) | G17: Edition 3 | H17: 7-bit Coded Character Set [ECMA-6 (07/1970)] | I17: Superseded | J17: ECMA Standard | L17: 1970-07
D18: characterSet | E18: refonly; relComplete | F18: ECMA-6 (08/1973) | G18: Edition 4 | H18: 7-bit Coded Character Set [ECMA-6 (08/1973)] | I18: Superseded | J18: ECMA Standard | L18: 1973-08 | M18: https://ecma-international.org/wp-content/uploads/ECMA-6_4th_edition_august_1973.pdf | N18: PDF
D19: characterSet | E19: refonly; relComplete | F19: ECMA-6 (03/1985) | G19: Edition 5 | H19: 7-bit Coded Character Set [ECMA-6 (03/1985)] | I19: Superseded | J19: ECMA Standard | L19: 1985-03 | M19: https://ecma-international.org/wp-content/uploads/ECMA-6_5th_edition_march_1985.pdf | N19: PDF
D20: characterSet | E20: refonly; relComplete | F20: ECMA-6 (12/1991) | G20: Edition 6 | H20: 7-bit Coded Character Set [ECMA-6 (12/1991)] | I20: Active | J20: ECMA Standard | L20: 1991-12 | M20: https://ecma-international.org/wp-content/uploads/ECMA-6_6th_edition_december_1991.pdf | N20: PDF
D21: characterSet | E21: refonly; relComplete | F21: ISO/R 646:1967 | G21: Edition 1 | H21: 6 and 7 Bit Coded Character Sets for Information Processing Interchange [ISO/R 646:1967] | I21: Withdrawn; Superseded | J21: ISO Recommendation | L21: 1967-12 | M21: https://www.iso.org/standard/963.html | N21: Request
D22: characterSet | E22: refonly; relComplete | F22: ISO 646:1973 | G22: Edition 1 | H22: Information Processing - ISO 7-bit Coded Character Set for Information Interchange [ISO 646:1973] | I22: Withdrawn; Superseded | J22: International Standard | L22: 1973-07 | M22: https://www.iso.org/standard/2823.html | N22: Request
D23: characterSet | E23: refonly; relComplete | F23: ISO 646:1983 | G23: Edition 2 | H23: Information Processing - ISO 7-bit Coded Character Set for Information Interchange [ISO 646:1983] | I23: Withdrawn; Superseded | J23: International Standard | L23: 1983-07 | M23: https://www.iso.org/standard/4776.html | N23: Request
D24: characterSet | E24: refonly; relComplete | F24: ISO/IEC 646:1991 | G24: Edition 3 | H24: Information Processing - ISO 7-bit Coded Character Set for Information Interchange [ISO/IEC 646:1991] | I24: Active | J24: International Standard | L24: 1991-12 | M24: https://www.iso.org/standard/4777.html | N24: Purchase
D25: characterSet | E25: refonly; relComplete | F25: CCITT Rec. V.3 (1968) | H25: International Alphabet Number 5 [CCITT Rec. V.3 (1968)] | I25: Superseded | J25: ITU-T Recommendation | L25: 1968 | Q25: https://search.itu.int/history/HistoryDigitalCollectionDocLibrary/4.255.43.en.1009.pdf | R25: PDF | S25: Other URL is Volume VIII of the White Book (1968), V.3 starts on page 11
D26: characterSet | E26: refonly; relComplete | F26: CCITT Rec. V.3 (1972) | H26: International Alphabet Number 5 [CCITT Rec. V.3 (1972)] | I26: Superseded | J26: ITU-T Recommendation | L26: 1972 | Q26: https://search.itu.int/history/HistoryDigitalCollectionDocLibrary/4.256.43.en.1015.pdf | R26: PDF | S26: Other URL is Volume VIII of the Green Book (1972), V.3 starts on page 47
D27: characterSet | E27: refonly; relComplete | F27: CCITT Rec. V.3 (10/1976) | G27: Edition 1 | H27: International Alphabet Number 5 [CCITT Rec. V.3 (10/1976)] | I27: Superseded | J27: ITU-T Recommendation | L27: 1976-10 | Q27: https://search.itu.int/history/HistoryDigitalCollectionDocLibrary/4.257.43.en.1015.pdf | R27: PDF | S27: Republication of CCITT Rec. V.3 (1972) || Other URL is Fascicle VIII.1 of the Orange Book (1976), V.3 starts on page 6
D28: characterSet | E28: refonly; relComplete | F28: CCITT Rec. V.3 (11/1980) | G28: Edition 2 | H28: International Alphabet Number 5 [CCITT Rec. V.3 (11/1980)] | I28: Superseded | J28: ITU-T Recommendation | L28: 1980-11 | Q28: https://search.itu.int/history/HistoryDigitalCollectionDocLibrary/4.258.43.en.1025.pdf | R28: PDF | S28: Republication of CCITT Rec. V.3 (1972) || Other URL is Fascicle VIII.1 of the Yellow Book (1980), V.3 starts on page 9
D29: characterSet | E29: refonly; relComplete | F29: CCITT Rec. T.50 (10/1984) | G29: Edition 3 | H29: International Alphabet Number 5 [CCITT Rec. T.50 (10/1984)] | I29: Superseded | J29: ITU-T Recommendation | L29: 1984-10 | Q29: https://search.itu.int/history/HistoryDigitalCollectionDocLibrary/4.259.43.en.1032.pdf | R29: PDF | S29: Other URL is Fascicle VII.3 of the Red Book (1984), T.50 starts on page 123
D30: characterSet | E30: refonly; relComplete | F30: CCITT Rec. T.50 (11/1988) | G30: Edition 4 | H30: International Alphabet Number 5 [CCITT Rec. T.50 (11/1988)] | I30: Superseded | J30: ITU-T Recommendation | L30: 1988-11 | M30: https://www.itu.int/rec/T-REC-T.50-198811-S | N30: PDF | Q30: https://search.itu.int/history/HistoryDigitalCollectionDocLibrary/4.260.43.en.1041.pdf | R30: PDF | S30: Republication of CCITT Rec. T.50 (10/1984) || Other URL is Fascicle VII.3 of the Blue Book (1988), T.50 starts on page 180
D31: characterSet | E31: refonly; relComplete | F31: ITU-T Rec. T.50 (09/1992) | G31: Edition 5 | H31: International Reference Alphabet (IRA) / Information Processing - ISO 7-bit Coded Character Set for Information Interchange [ITU-T Rec T.50 (09/1992)] | I31: Active | J31: ITU-T Recommendation | L31: 1992-09 | M31: https://www.itu.int/rec/T-REC-T.50-199209-I | N31: PDF
D32: characterSet | E32: refonly; relComplete | F32: RFC20 | H32: ASCII Format for Network Interchange | I32: Active | J32: Internet Standard | K32: Legacy | L32: 1969-10-16 | M32: https://www.rfc-editor.org/rfc/rfc20.txt | N32: TXT-ASCII | O32: https://www.rfc-editor.org/rfc/rfc20.txt | P32: https://www.rfc-editor.org/rfc/rfc20.html | Q32: https://datatracker.ietf.org/doc/rfc20/ | R32: IETF Datatracker | S32: Restatement of US-ASCII [USAS X3.4-1968]
D34: characterSet | E34: refonly; relComplete | F34: ECMA-35 (12/1971) | G34: Edition 1 | H34: Extension of the 7-bit Coded Character Set [ECMA-35 (12/1971)] | I34: Superseded | J34: ECMA Standard | L34: 1971-12 | M34: https://ecma-international.org/wp-content/uploads/ECMA-35_1st_edition_december_1971.pdf | N34: PDF
D35: characterSet | E35: refonly; relComplete | F35: ECMA-35 (01/1980) | G35: Edition 2 | H35: Extension of the 7-bit Coded Character Set [ECMA-35 (01/1980)] | I35: Superseded | J35: ECMA Standard | L35: 1980-01 | M35: https://ecma-international.org/wp-content/uploads/ECMA-35_2nd_edition_january_1980.pdf | N35: PDF
D36: characterSet | E36: refonly; relComplete | F36: ECMA-35 (01/1982) | G36: Edition 3 | H36: Code Extension Techniques [ECMA-35 (01/1982)] | I36: Superseded | J36: ECMA Standard | L36: 1982-01 | M36: https://ecma-international.org/wp-content/uploads/ECMA-35_3rd_edition_january_1982.pdf | N36: PDF
D37: characterSet | E37: refonly; relComplete | F37: ECMA-35 (03/1985) | G37: Edition 4 | H37: Code Extension Techniques [ECMA-35 (03/1985)] | I37: Superseded | J37: ECMA Standard | L37: 1985-03 | M37: https://ecma-international.org/wp-content/uploads/ECMA-35_4th_edition_march_1985.pdf | N37: PDF
D38: characterSet | E38: noReview; refonly; relComplete | F38: ECMA-35 (06/1993) | G38: Edition 5 | H38: Character Code Structure and Extension Techniques [ECMA-35 (06/1993)] | I38: Superseded | J38: ECMA Standard | L38: 1993-06
D39: characterSet | E39: refonly; relComplete | F39: ECMA-35 (12/1994) | G39: Edition 6 | H39: Character Code Structure and Extension Techniques [ECMA-35 (12/1994)] | I39: Active | J39: ECMA Standard | L39: 1994-12 | M39: https://ecma-international.org/wp-content/uploads/ECMA-35_6th_edition_december_1994.pdf | N39: PDF
D40: characterSet | E40: refonly; relComplete | F40: ISO 2022:1973 | G40: Edition 1 | H40: Information processing — Code extension techniques for use with the ISO 7-bit coded character set [ISO 2022:1973] | I40: Withdrawn; Superseded | J40: International Standard | L40: 1973-07 | M40: https://www.iso.org/standard/1920.html | N40: Request
D41: characterSet | E41: refonly; relComplete | F41: ISO 2022:1982 | G41: Edition 2 | H41: Information processing — ISO 7-bit and 8-bit coded character sets — Code extension techniques [ISO 2022:1982] | I41: Withdrawn; Superseded | J41: International Standard | L41: 1982-12 | M41: https://www.iso.org/standard/6790.html | N41: Request
...

Sheet Format
A1: formatId | B1: createdTimestamp | C1: updatedTimestamp | D1: formatType | E1: shortName | F1: fullName | G1: status | H1: notes | I1: DNI_notes
D2: characterEncoding | E2: US-ASCII | F2: American Standard Code for Information Interchange (7-bit code unit)
D3: characterEncoding | E3: ISO/IEC 646 IRV | F3: ISO/IEC 646 International Reference Version | H3: Formerly known as Internation Alphabet 5 (IA5)
D4: characterEncoding | E4: Unicode | F4: Unicode Character Encoding Forms | H4: Superset of Unicode encoding schemes
D5: characterEncoding | E5: UTF-32 | F5: UTF-32 | H5: 32-bit fixed code unit, endian-neutral, BOM allowed
D6: characterEncoding | E6: UTF-32BE | F6: UTF-32 big-endian | H6: 32-bit fixed code unit, big-endian, BOM prohibited
D7: characterEncoding | E7: UTF-32LE | F7: UTF-32 little-endian | H7: 32-bit fixed code unit, little-endian, BOM prohibited
D8: characterEncoding | E8: UTF-16 | F8: UTF-16 | H8: 16-bit code unit, 2 code units max per character, endian-neutral, BOM allowed
D9: characterEncoding | E9: UTF-16BE | F9: UTF-16 big-endian | H9: 16-bit code unit, 2 code units max per character, big-endian, BOM prohibited
D10: characterEncoding | E10: UTF-16LE | F10: UTF-16 little-endian | H10: 16-bit code unit, 2 code units max per character, little-endian, BOM prohibited
D11: characterEncoding | E11: UTF-8 | F11: UTF-8 | H11: 8-bit code unit, 4 code units max per character, BOM allowed
D12: binaryEncoding | E12: Base64 | F12: Base64 binary encoding (standard)
D13: binaryEncoding | E13: Base64URL | F13: Base64 binary encoding (URL and filename safe)
D14: dataEncoding | E14: PEM | F14: Privacy Enhanced Mail derived data encoding structure
D15: interfaceLanguage | E15: ASN.1 | F15: Abstract Syntax Notation 1
D16: dataEncoding | E16: ASN.1 BER | F16: ASN.1 Basic Encoding Rules encoded data
D17: dataEncoding | E17: ASN.1 CER | F17: ASN.1 Canonical Encoding Rules encoding data
D18: dataEncoding | E18: ASN.1 DER | F18: ASN.1 Distinguished Encoding Rules encoded data
D19: markupLanguage | E19: HTML | F19: Hypertext Markup Language
D20: markupLanguage | E20: XML | F20: Extensible Markup Language
D21: dataEncoding | E21: JSON | F21: JavaScript Object Notation
D22: dataEncoding | E22: JSONL | F22: JavaScript Object Notation - Lines
D23: dataEncoding | E23: JSONC | F23: JavaScript Object Notation with Comments
D24: dataEncoding | E24: JSON5 | F24: JSON5 Data Interchange Format | H24: Extended JSON with features from EcmaScript 5.1 || Informally known as 'JSON for Humans'
D25: dataEncoding | E25: CBOR | F25: Concise Binary Object Representation
D26: messageFormat | E26: Internet Message Format | F26: Internet Message Format

Sheet AuthorityDraft
A1: reference:ID:string | B1: title:string | C1: status:string[] | D1: type:string | E1: stream:string
A2: draft-hickman-netscape-ssl | B2: The SSL Protocol | C2: Archived; Expired | D2: Internet-Draft
A3: draft-ietf-oauth-v2 | B3: The OAuth 2.0 Authorization Framework | C3: Became RFC | D3: Internet-Draft | E3: IETF
A4: draft-ietf-oauth-v2-http-mac | B4: OAuth 2.0 Message Authentication Code (MAC) Tokens | C4: Expired | D4: Internet-Draft | E4: IETF
A5: draft-ietf-oauth-saml2-bearer | B5: Security Assertion Markup Language (SAML) 2.0 Profile for OAuth 2.0 Client Authentication and Authorization Grants | C5: Became RFC | D5: Internet-Draft | E5: IETF
A6: draft-ietf-oauth-v2-threatmodel | B6: OAuth 2.0 Threat Model and Security Considerations | C6: Became RFC | D6: Internet-Draft | E6: IETF
A7: draft-hardt-oauth | B7: OAuth Web Resource Authorization Profiles | C7: Expired | D7: Internet-Draft | E7: Individual
A8: draft-ietf-httpbis-p7-auth | B8: Hypertext Transfer Protocol (HTTP/1.1): Authentication | C8: Became RFC | D8: Internet-Draft | E8: IETF
A9: draft-ietf-jose-json-web-signature | B9: JSON Web Signature (JWS) | C9: Became RFC | D9: Internet-Draft | E9: IETF
A10: draft-ietf-jose-json-web-encryption | B10: JSON Web Encryption (JWE) | C10: Became RFC | D10: Internet-Draft | E10: IETF
A11: draft-ietf-jose-json-web-key | B11: JSON Web Key (JWK) | C11: Became RFC | D11: Internet-Draft | E11: IETF
A12: draft-ietf-jose-json-web-algorithms | B12: JSON Web Algorithms (JWA) | C12: Became RFC | D12: Internet-Draft | E12: IETF
A13: draft-ietf-oauth-json-web-token | B13: JSON Web Token (JWT) | C13: Became RFC | D13: Internet-Draft | E13: IETF
A14: draft-recordon-oauth-v2-device | B14: OAuth 2.0 Device Profile | C14: Expired | D14: Internet-Draft | E14: Individual
... A38: draft-jones-simple-web-discovery | B38: Simple Web Discovery (SWD) | C38: Expired | D38: Internet-Draft | E38: Individual

Sheet Revision
A1: reference:ID:string | B1: revisionId:string | C1: title:string | D1: status:string[] | E1: type:string | F1: stream:string | G1: canonicalUrl:string | H1: canonicalFormat:string | I1: plainTextUrl:string | J1: htmlUrl:string | K1: otherUrl:string | L1: otherFormat:string
A2: draft-hickman-netscape-ssl-00 | B2: 00 | C2: The SSL Protocol | D2: Archived; Expired | E2: Internet-Draft | G2: https://www.ietf.org/archive/id/draft-hickman-netscape-ssl-00.txt | H2: TXT-ASCII | I2: https://www.ietf.org/archive/id/draft-hickman-netscape-ssl-00.txt
A3: draft-ietf-oauth-v2-31 | B3: 31 | C3: The OAuth 2.0 Authorization Framework | D3: Became RFC | E3: Internet-Draft | F3: IETF | G3: https://www.ietf.org/archive/id/draft-ietf-oauth-v2-31.xml | H3: RFCXML | I3: https://www.ietf.org/archive/id/draft-ietf-oauth-v2-31.txt
A4: draft-ietf-oauth-v2-http-mac-01 | B4: 01 | C4: HTTP Authentication: MAC Access Authentication | D4: Expired | E4: Internet-Draft | F4: IETF | G4: https://www.ietf.org/archive/id/draft-ietf-oauth-v2-http-mac-01.txt | H4: TXT-ASCII | I4: https://www.ietf.org/archive/id/draft-ietf-oauth-v2-http-mac-01.txt
A5: draft-ietf-oauth-saml2-bearer-14 | B5: 14 | C5: SAML 2.0 Bearer Assertion Profiles for OAuth 2.0 | D5: Updated | E5: Internet-Draft | F5: IETF | G5: https://www.ietf.org/archive/id/draft-ietf-oauth-saml2-bearer-14.txt | H5: TXT-ASCII | I5: https://www.ietf.org/archive/id/draft-ietf-oauth-saml2-bearer-14.txt
A6: draft-ietf-oauth-v2-threatmodel-08 | B6: 08 | C6: OAuth 2.0 Threat Model and Security Considerations | D6: Became RFC | E6: Internet-Draft | F6: IETF | G6: https://www.ietf.org/archive/id/draft-ietf-oauth-v2-threatmodel-08.txt | H6: TXT-ASCII | I6: https://www.ietf.org/archive/id/draft-ietf-oauth-v2-threatmodel-08.txt
A7: draft-hardt-oauth-00 | B7: 00 | C7: OAuth Web Resource Authorization Profiles | D7: Expired | E7: Internet-Draft | F7: IETF | G7: https://datatracker.ietf.org/doc/id/draft-hardt-oauth-00.txt | H7: TXT-ASCII | I7: https://datatracker.ietf.org/doc/id/draft-hardt-oauth-00.txt
A8: draft-ietf-httpbis-p7-auth-21 | B8: 21 | C8: Hypertext Transfer Protocol (HTTP/1.1): Authentication | D8: Updated | E8: Internet-Draft | F8: IETF | G8: https://www.ietf.org/archive/id/draft-ietf-httpbis-p7-auth-21.txt | H8: TXT-ASCII | I8: https://www.ietf.org/archive/id/draft-ietf-httpbis-p7-auth-21.txt
A9: openid-connect-core-1_0-35 | B9: 35 | C9: OpenID Connect Core 1.0 | D9: Became Final Spec; Updated | E9: Work Group Draft | F9: OIDF | G9: https://openid.net/specs/openid-connect-core-1_0-35.xml | H9: RFCXML | I9: https://openid.net/specs/openid-connect-core-1_0-35.txt | J9: https://openid.net/specs/openid-connect-core-1_0-35.html
A10: openid-connect-core-1_0-22 | B10: 22 | C10: OpenID Connect Core 1.0 | D10: Became Final Spec; Updated | E10: Work Group Draft | F10: OIDF | G10: https://openid.net/specs/openid-connect-core-1_0-22.xml | H10: RFCXML | I10: https://openid.net/specs/openid-connect-core-1_0-22.txt | J10: https://openid.net/specs/openid-connect-core-1_0-22.html
A11: openid-connect-core-1_0-18 | B11: 18 | C11: OpenID Connect Core 1.0 | D11: Became Final Spec; Updated | E11: Work Group Draft | F11: OIDF | G11: https://openid.net/specs/openid-connect-core-1_0-18.xml | H11: RFCXML | I11: https://openid.net/specs/openid-connect-core-1_0-18.txt | J11: https://openid.net/specs/openid-connect-core-1_0-18.html
A12: openid-connect-core-1_0-12 | B12: 12 | C12: OpenID Connect Core 1.0 | D12: Updated | E12: Work Group Draft | F12: OIDF | G12: https://openid.net/specs/openid-connect-core-1_0-12.xml | H12: RFCXML | I12: https://openid.net/specs/openid-connect-core-1_0-12.txt | J12: https://openid.net/specs/openid-connect-core-1_0-12.html
A13: openid-connect-standard-1_0-21 | B13: 21 | C13: OpenID Connect Standard 1.0 | D13: Replaced | E13: Work Group Draft | F13: OIDF | G13: https://openid.net/specs/openid-connect-standard-1_0-21.xml | H13: RFCXML | I13: https://openid.net/specs/openid-connect-standard-1_0-21.txt | J13: https://openid.net/specs/openid-connect-standard-1_0-21.html
A14: openid-connect-messages-1_0-20 | B14: 20 | C14: OpenID Connect Messages 1.0 | D14: Replaced | E14: Work Group Draft | F14: OIDF | G14: https://openid.net/specs/openid-connect-messages-1_0-20.xml | H14: RFCXML | I14: https://openid.net/specs/openid-connect-messages-1_0-20.txt | J14: https://openid.net/specs/openid-connect-messages-1_0-20.html
A15: openid-connect-messages-1_0-12 | B15: 12 | C15: OpenID Connect Messages 1.0 | D15: Updated | E15: Work Group Draft | F15: OIDF | G15: https://openid.net/specs/openid-connect-messages-1_0-12.txt | H15: TXT-ASCII | I15: https://openid.net/specs/openid-connect-messages-1_0-12.txt | J15: https://openid.net/specs/openid-connect-messages-1_0-12.html
A16: draft-ietf-jose-json-web-signature-41 | B16: 41 | C16: JSON Web Signature (JWS) | D16: Became RFC | E16: Internet-Draft | F16: IETF | G16: https://www.ietf.org/archive/id/draft-ietf-jose-json-web-signature-41.xml | H16: RFCXML | I16: https://www.ietf.org/archive/id/draft-ietf-jose-json-web-signature-41.txt
A17: draft-ietf-jose-json-web-encryption-40 | B17: 40 | C17: JSON Web Encryption (JWE) | D17: Became RFC | E17: Internet-Draft | F17: IETF | G17: https://www.ietf.org/archive/id/draft-ietf-jose-json-web-encryption-40.xml | H17: RFCXML | I17: https://www.ietf.org/archive/id/draft-ietf-jose-json-web-encryption-40.txt
A18: draft-ietf-jose-json-web-key-41 | B18: 41 | C18: JSON Web Key (JWK) | D18: Became RFC | E18: Internet-Draft | F18: IETF | G18: https://www.ietf.org/archive/id/draft-ietf-jose-json-web-key-41.xml | H18: RFCXML | I18: https://www.ietf.org/archive/id/draft-ietf-jose-json-web-key-41.txt
A19: draft-ietf-jose-json-web-algorithms-40 | B19: 40 | C19: JSON Web Algorithms (JWA) | D19: Became RFC | E19: Internet-Draft | F19: IETF | G19: https://www.ietf.org/archive/id/draft-ietf-jose-json-web-algorithms-40.xml | H19: RFCXML | I19: https://www.ietf.org/archive/id/draft-ietf-jose-json-web-algorithms-40.txt
A20: draft-ietf-oauth-json-web-token-32 | B20: 32 | C20: JSON Web Token (JWT) | D20: Became RFC | E20: Internet-Draft | F20: IETF | G20: https://www.ietf.org/archive/id/draft-ietf-oauth-json-web-token-32.xml | H20: RFCXML | I20: https://www.ietf.org/archive/id/draft-ietf-oauth-json-web-token-32.txt
A21: draft-recordon-oauth-v2-device-00 | B21: 00 | C21: OAuth 2.0 Device Profile | D21: Expired | E21: Internet-Draft | F21: Individual | G21: https://www.ietf.org/archive/id/draft-recordon-oauth-v2-device-00.txt | H21: TXT-ASCII | I21: https://www.ietf.org/archive/id/draft-recordon-oauth-v2-device-00.txt
A22: openid-connect-discovery-1_0-37 | B22: 37 | C22: OpenID Connect Discovery 1.0 | D22: Became Final Spec | E22: Work Group Draft | F22: OIDF | G22: https://openid.net/specs/openid-connect-discovery-1_0-37.xml | H22: RFCXML | I22: https://openid.net/specs/openid-connect-discovery-1_0-37.txt | J22: https://openid.net/specs/openid-connect-discovery-1_0-37.html
A23: openid-connect-discovery-1_0-25 | B23: 25 | C23: OpenID Connect Discovery 1.0 | D23: Became Final Spec; Updated | E23: Work Group Draft | F23: OIDF | G23: https://openid.net/specs/openid-connect-discovery-1_0-25.xml | H23: RFCXML | I23: https://openid.net/specs/openid-connect-discovery-1_0-25.txt | J23: https://openid.net/specs/openid-connect-discovery-1_0-25.html
A24: openid-connect-discovery-1_0-22 | B24: 22 | C24: OpenID Connect Discovery 1.0 | D24: Became Final Spec; Updated | E24: Work Group Draft | F24: OIDF | G24: https://openid.net/specs/openid-connect-discovery-1_0-22.xml | H24: RFCXML | I24: https://openid.net/specs/openid-connect-discovery-1_0-22.txt | J24: https://openid.net/specs/openid-connect-discovery-1_0-22.html
A25: openid-connect-registration-1_0-39 | B25: 39 | C25: OpenID Connect Dynamic Client Registration 1.0 | D25: Became Final Spec | E25: Work Group Draft | F25: OIDF | G25: https://openid.net/specs/openid-connect-registration-1_0-39.xml | H25: RFCXML | I25: https://openid.net/specs/openid-connect-registration-1_0-39.txt | J25: https://openid.net/specs/openid-connect-registration-1_0-39.html
A26: openid-connect-registration-1_0-28 | B26: 28 | C26: OpenID Connect Dynamic Client Registration 1.0 | D26: Became Final Spec; Updated | E26: Work Group Draft | F26: OIDF | G26: https://openid.net/specs/openid-connect-registration-1_0-28.xml | H26: RFCXML | I26: https://openid.net/specs/openid-connect-registration-1_0-28.txt | J26: https://openid.net/specs/openid-connect-registration-1_0-28.html
A27: openid-connect-registration-1_0-24 | B27: 24 | C27: OpenID Connect Dynamic Client Registration 1.0 | D27: Became Final Spec; Updated | E27: Work Group Draft | F27: OIDF | G27: https://openid.net/specs/openid-connect-registration-1_0-24.xml | H27: RFCXML | I27: https://openid.net/specs/openid-connect-registration-1_0-24.txt | J27: https://openid.net/specs/openid-connect-registration-1_0-24.html
A28: openid-connect-registration-1_0-08 | B28: 08 | C28: OpenID Connect Dynamic Client Registration 1.0 | D28: Updated | E28: Work Group Draft | F28: OIDF | G28: https://openid.net/specs/openid-connect-registration-1_0-08.xml | H28: RFCXML | I28: https://openid.net/specs/openid-connect-registration-1_0-08.txt | J28: https://openid.net/specs/openid-connect-registration-1_0-08.html
A29: openid-connect-rpinitiated-1_0-04 | B29: 04 | C29: OpenID Connect RP-Initiated Logout 1.0 | D29: Became Final Spec | E29: Work Group Draft | F29: OIDF | G29: https://openid.net/specs/openid-connect-rpinitiated-1_0-04.xml | H29: RFCXML | I29: https://openid.net/specs/openid-connect-rpinitiated-1_0-04.txt | J29: https://openid.net/specs/openid-connect-rpinitiated-1_0-04.html
A30: openid-connect-session-1_0-32 | B30: 32 | C30: OpenID Connect Session Management 1.0 | D30: Became Final Spec | E30: Work Group Draft | F30: OIDF | G30: https://openid.net/specs/openid-connect-session-1_0-32.xml | H30: RFCXML | I30: https://openid.net/specs/openid-connect-session-1_0-32.txt | J30: https://openid.net/specs/openid-connect-session-1_0-32.html
A31: openid-connect-frontchannel-1_0-07 | B31: 07 | C31: OpenID Connect Front-Channel Logout 1.0 | D31: Became Final Spec | E31: Work Group Draft | F31: OIDF | G31: https://openid.net/specs/openid-connect-frontchannel-1_0-07.xml | H31: RFCXML | I31: https://openid.net/specs/openid-connect-frontchannel-1_0-07.txt | J31: https://openid.net/specs/openid-connect-frontchannel-1_0-07.html
A32: openid-connect-backchannel-1_0-13 | B32: 13 | C32: OpenID Connect Back-Channel Logout 1.0 | D32: Became Final Spec | E32: Work Group Draft | F32: OIDF | G32: https://openid.net/specs/openid-connect-backchannel-1_0-13.xml | H32: RFCXML | I32: https://openid.net/specs/openid-connect-backchannel-1_0-13.txt | J32: https://openid.net/specs/openid-connect-backchannel-1_0-13.html
A33: openid-connect-backchannel-1_0-10 | B33: 10 | C33: OpenID Connect Back-Channel Logout 1.0 | D33: Became Final Spec | E33: Work Group Draft | F33: OIDF | G33: https://openid.net/specs/openid-connect-backchannel-1_0-10.xml | H33: RFCXML | I33: https://openid.net/specs/openid-connect-backchannel-1_0-10.txt | J33: https://openid.net/specs/openid-connect-backchannel-1_0-10.html
... A45: fapi-attacker-model-2_0-05 | B45: 05 | C45: FAPI 2.0 Attacker Model | D45: Became Final Spec | E45: Work Group Draft | F45: OIDF | G45: https://openid.net/specs/fapi-attacker-model-2_0-05.xml | H45: RFCXML | I45: https://openid.net/specs/fapi-attacker-model-2_0-05.md | J45: https://openid.net/specs/fapi-attacker-model-2_0-05.html
A46: oauth-v2-jarm-04 | B46: 04 | C46: JWT Secured Authorization Response Mode for OAuth 2.0 (JARM) | D46: Became Final Spec | E46: Work Group Draft | F46: OIDF | G46: https://openid.net/specs/oauth-v2-jarm-04.html | H46: HTML | J46: https://openid.net/specs/oauth-v2-jarm-04.html
A47: openid-ciba-core-1_0-04 | B47: 04 | C47: OpenID Connect Client-Initiated Backchannel Authentication Flow - Core 1.0 | D47: Updated | E47: Work Group Draft | F47: OIDF | G47: https://openid.net/specs/openid-client-initiated-backchannel-authentication-core-1_0-04.xml | H47: RFCXML | I47: https://openid.net/specs/openid-client-initiated-backchannel-authentication-core-1_0-04.txt | J47: https://openid.net/specs/openid-client-initiated-backchannel-authentication-core-1_0-04.html
A48: draft-jones-simple-web-discovery-04 | B48: 04 | C48: Simple Web Discovery (SWD) | D48: Expired | E48: Internet-Draft | F48: Individual | G48: https://www.ietf.org/archive/id/draft-jones-simple-web-discovery-04.txt | H48: TXT-ASCII | I48: https://www.ietf.org/archive/id/draft-jones-simple-web-discovery-04.txt
A49: draft-jones-simple-web-discovery-00 | B49: 00 | C49: Simple Web Discovery (SWD) | D49: Updated | E49: Internet-Draft | F49: Individual | G49: https://www.ietf.org/archive/id/draft-jones-simple-web-discovery-00.txt | H49: TXT-ASCII | I49: https://www.ietf.org/archive/id/draft-jones-simple-web-discovery-00.txt

Sheet Protocol
A1: name:ID:string
A2: OAuth
A3: OpenID Connect
A4: OpenID
A5: SAML

Sheet ProtocolVersion
A1: versionedName:ID:string
A2: OAuth 2.0
A3: OpenID Connect 1.0
A4: OpenID 2.0
A5: OpenID 1.1
A6: OpenID 1.0
A7: SAML 1.0
A8: SAML 1.1
A9: SAML 2.0

Sheet ProtocolFeature
A1: name:ID:string | B1: type:string
A2: Resource Owner | B2: Role
A3: Resource Server | B3: Role
A4: Client | B4: Role
A5: Authorization Server | B5: Role
A6: Authorization Code | B6: Authorization Grant
A7: Implicit | B7: Authorization Grant
A8: Resource Owner Password Credentials | B8: Authorization Grant
A9: Client Credentials | B9: Authorization Grant
A10: Extension Grants | B10: Authorization Grant
A11: Access Token | B11: Token Type
A12: Refresh Token | B12: Token Type
... A23: Token Endpoint | B23: Protocol Endpoint

Sheet Definitions
A1: Status | E1: Affiliation | H1: Reference Type | K1: Relationship
A2: Defines the state of a given authority. | E2: Defines relationships between organizations. | H2: Defines role of upstream reference. | K2: Defines similarity between two authorities.
A4: Status | B4: Relationship | C4: Definition | E4: Value | F4: Definition | H4: Value | I4: Definition | K4: Value | L4: Definition
A5: Active | C5: Authority is approved and published by its controlling organization and not otherwise Obsoleted or Superseded. | E5: accredits | F5: [Source] recognizes or authorizes external [target] to serve as a subordinate org. | H5: normative | I5: [Target] establishes requirements which are incorporated by reference into [source]. | K5: republication | L5: [Source] is a subsequent publication of the same text of [target], such as via reaffirmation of an existing authority.
A6: Unpublished | C6: Authority is approved by its controlling organization but has not yet been published. | E6: sponsors | F6: [Source] provides meaningful support to the continued existence of [target]. | H6: informative | I6: [Target] informs the development of [source], without binding [source] to its requirements. | K6: textually equivalent | L6: [Source] and [target] have nearly identical text and the same technical meaning. Referenced as "common" standards between ITU-T and ISO/IEC.
A7: Draft | C7: Authority is a draft revision of a prospective specification. | E7: national representative | F7: [Source] acts as a liaison to an international organization ([target]) in service of an independent nation state. | H7: ongoing | I7: [Target] is an authority with ongoing, continued updates; [source] explicitly or implicitly relies on ongoing updates to the [target] ([target] should be an AuthorityGroup). | K7: technically equivalent | L7: [Source] and [target] have the same technical meaning although the text is not identical. Referenced as "twinned" standards between ITU-T and ISO/IEC.
A8: Withdrawn | C8: Authority has been removed from effective status and publication by its controlling organization; the specification defined by the Authority must no longer be used. | E8: technical advisory group | F8: [Source] serves as an independent consultant on technical matters to a broader [target] organization. | K8: partially equivalent | L8: [Source] is technically equivalent to a portion of [target]; equivalent portion explained in notes field.
A9: Deprecated | B9: DEPRECATES | C9: Authority has been removed from effective status via specification; the specification defined by the Authority must no longer be used. | K9: influenced | L9: [Source] significantly influenced the design of [target] without directly EXTENDing or OBSOLETing the [source].
A10: Superseded | B10: SUPERSEDES | C10: Authority has been replaced with an updated specification; the specification defined by the Authority should no longer be used.
A11: Obsoleted | B11: OBSOLETES | C11: Authority has been updated or extended by another specification without being replaced; the specification defined by the Authority may continue to be used.
A12: Updated | B12: UPDATES | C12: Authority has been updated by another specification; may be indicated with any other status.
A13: Errata | C13: Authority has documented errata; may be indicated with any other status.
A14: Expired | C14: A Draft Authority without activity for an extended period may be inactivated by its controlling organization, such Authorities will be marked as Expired.

Sheet _Validation
A1: NodeTypes | C1: NodeType | D1: NodeTypeAttr | F1: {=TRANSPOSE(_xlfn.UNIQUE(__val_NodeTypeAttrs[NodeType]))} -> ControllingOrg | G1: Authority | H1: AuthorityGroup | I1: Format | AA1: RelationshipTypes
